# 🔧 SYNCHRONISATIONS-PROBLEM BEHOBEN

## 🐛 PROBLEM
Todo #212 wurde in der **Datenbank als `completed`** markiert, aber das **Hook-System dachte es sei noch aktiv**.

## 🔍 URSACHE
Das Hook-System (`todo_manager.py`) prüft die Existenz von `/tmp/CURRENT_TODO_ID`:
- Wenn die Datei existiert → nimmt an, dass Todo noch aktiv ist
- Versucht es dann "abzuschließen" mit `handle_completion()`
- **Problem:** Die Datei wurde nicht gelöscht nach der manuellen Completion

## ✅ LÖSUNG
1. **Sofortmaßnahme:** Temporäre Dateien manuell gelöscht:
   - `/tmp/CURRENT_TODO_ID`
   - `/tmp/TASK_COMPLETED` 
   - `/tmp/SPECIFIC_TODO_MODE`

2. **Langfristige Lösung:** Hook-System sollte robuster sein:
   - Vor "WARNING still active" → Datenbank-Status prüfen
   - Wenn DB sagt `completed` → temporäre Dateien löschen
   - Synchronisation zwischen DB und Dateisystem sicherstellen

## 📝 BETROFFENER CODE
```python
# In todo_manager.py, Zeile 132-139
if Path(CONFIG["paths"]["current_todo"]).exists():
    with open(CONFIG["paths"]["current_todo"]) as f:
        active_id = f.read().strip()
    log("WARNING", f"Todo #{active_id} is still active. Completing it first.")
    handle_completion()  # Dies sollte DB-Status prüfen!
```

## 🎯 EMPFEHLUNG
Hook-System Update erforderlich für bessere Synchronisation zwischen:
- Datenbank-Status (source of truth)
- Temporäre Dateien (nur Cache)

**Status:** ✅ Problem behoben - System wieder synchron